Workbook

Sheet Assumptions & Cash Flow
C1: Assumptions & Cash Flow
C6: General Assumptions | K6: 0 | L6: =+K6+1 -> 1 | M6: =+L6+1 -> 2 | N6: =+M6+1 -> 3 | O6: =+N6+1 -> 4 | P6: =+O6+1 -> 5 | Q6: =+P6+1 -> 6 | R6: =+Q6+1 -> 7 | S6: =+R6+1 -> 8 | ... V6: =+U6+1 -> 11
D7: Project Name | G7: Project Destined | K7: =+G11 -> 46022 | L7: =EDATE(K7,12) -> 46387 | M7: =EDATE(L7,12) -> 46752 | N7: =EDATE(M7,12) -> 47118 | O7: =EDATE(N7,12) -> 47483 | P7: =EDATE(O7,12) -> 47848 | Q7: =EDATE(P7,12) -> 48213 | R7: =EDATE(Q7,12) -> 48579 | S7: =EDATE(R7,12) -> 48944 | ... V7: =EDATE(U7,12) -> 50040
D8: Underwriter | G8: Tanish Chanthan | J8: Revenues
D9: # of Units | G9: 28 | J9: Gross Potential Rent | L9: ='Rent Roll'!K17 -> 519367.5 | M9: ='Rent Roll'!L17 -> 554220.68 | N9: ='Rent Roll'!M17 -> 594187.01 | O9: ='Rent Roll'!N17 -> 634067.87 | P9: ='Rent Roll'!O17 -> 673458.76 | Q9: ='Rent Roll'!P17 -> 698464.17 | R9: ='Rent Roll'!Q17 -> 724402.14 | S9: ='Rent Roll'!R17 -> 751307.62 | ... V9: ='Rent Roll'!U17 -> 838198.4
D10: Square Footage | G10: 23865 | J10: Vacancy Allowance | L10: ='Rent Roll'!K21 -> -77905.125 | M10: ='Rent Roll'!L21 -> -110844.14 | N10: ='Rent Roll'!M21 -> -89128.051 | O10: ='Rent Roll'!N21 -> -63406.787 | P10: ='Rent Roll'!O21 -> -67345.876 | Q10: ='Rent Roll'!P21 -> -34923.208 | R10: ='Rent Roll'!Q21 -> -21732.064 | S10: ='Rent Roll'!R21 -> -22539.229 | ... V10: ='Rent Roll'!U21 -> -25145.952
D11: Purchase Date | G11: 46022 | J11: Credit Loss | L11: =-L9*$G$22 -> -10387.35 | M11: =-M9*$G$22 -> -11084.414 | N11: =-N9*$G$22 -> -11883.74 | O11: =-O9*$G$22 -> -12681.357 | P11: =-P9*$G$22 -> -13469.175 | Q11: =-Q9*$G$22 -> -13969.283 | R11: =-R9*$G$22 -> -14488.043 | S11: =-S9*$G$22 -> -15026.152 | ... V11: =-V9*$G$22 -> -16763.968
D12: Total Hold Period | G12: 10 | J12: Other Income | L12: =G9*G23 -> 70000 | M12: =L12*(1+$G$22) -> 71400 | N12: =M12*(1+$G$22) -> 72828 | O12: =N12*(1+$G$22) -> 74284.56 | P12: =O12*(1+$G$22) -> 75770.251 | Q12: =P12*(1+$G$22) -> 77285.656 | R12: =Q12*(1+$G$22) -> 78831.369 | S12: =R12*(1+$G$22) -> 80407.997 | T12: =S12*(1+$G$22) -> 82016.157 | ... V12: =U12*(1+$G$22) -> 85329.609
D13: Sale Date | G13: 49674 | J13: Effective Gross Income | L13: =SUM(L9:L12) -> 501075.03 | M13: =SUM(M9:M12) -> 503692.13 | N13: =SUM(N9:N12) -> 566003.22 | O13: =SUM(O9:O12) -> 632264.29 | P13: =SUM(P9:P12) -> 668413.96 | Q13: =SUM(Q9:Q12) -> 726857.33 | R13: =SUM(R9:R12) -> 767013.41 | S13: =SUM(S9:S12) -> 794150.24 | ... V13: =SUM(V9:V12) -> 881618.09
D14: Property Purchase Price | G14: 6500000
D15: Closing Costs & Permits (as a % of Purchase Price) | G15: 0.015 | J15: Operating Expenses
D16: Closing Costs & Permits | G16: =G15*G14 -> 97500 | J16: Payroll | L16: =G27 -> 55000 | M16: =L16*(1+$G$36) -> 56650 | N16: =M16*(1+$G$36) -> 58349.5 | O16: =N16*(1+$G$36) -> 60099.985 | P16: =O16*(1+$G$36) -> 61902.985 | Q16: =P16*(1+$G$36) -> 63760.074 | R16: =Q16*(1+$G$36) -> 65672.876 | S16: =R16*(1+$G$36) -> 67643.063 | T16: =S16*(1+$G$36) -> 69672.354 | ... V16: =U16*(1+$G$36) -> 73915.401
D17: Debt Origination Costs (% of Debt) | G17: 0.0125 | J17: Utilities | L17: =G28 -> 34000 | M17: =L17*(1+$G$36) -> 35020 | N17: =M17*(1+$G$36) -> 36070.6 | O17: =N17*(1+$G$36) -> 37152.718 | P17: =O17*(1+$G$36) -> 38267.3 | Q17: =P17*(1+$G$36) -> 39415.319 | R17: =Q17*(1+$G$36) -> 40597.778 | S17: =R17*(1+$G$36) -> 41815.711 | T17: =S17*(1+$G$36) -> 43070.183 | ... V17: =U17*(1+$G$36) -> 45693.157
D18: Debt Origination Costs ($) | G18: =G17*G48 -> 39099.097 | J18: Contracts | L18: =G29 -> 15000 | M18: =L18*(1+$G$36) -> 15450 | N18: =M18*(1+$G$36) -> 15913.5 | O18: =N18*(1+$G$36) -> 16390.905 | P18: =O18*(1+$G$36) -> 16882.632 | Q18: =P18*(1+$G$36) -> 17389.111 | R18: =Q18*(1+$G$36) -> 17910.784 | S18: =R18*(1+$G$36) -> 18448.108 | T18: =S18*(1+$G$36) -> 19001.551 | ... V18: =U18*(1+$G$36) -> 20158.746
D19: Going in Cap Rate | G19: =L27/G14 -> 0.048121965 | J19: Repairs & Maintenance | L19: =G30*G9 -> 14000 | M19: =L19*(1+$G$36) -> 14420 | N19: =M19*(1+$G$36) -> 14852.6 | O19: =N19*(1+$G$36) -> 15298.178 | P19: =O19*(1+$G$36) -> 15757.123 | Q19: =P19*(1+$G$36) -> 16229.837 | R19: =Q19*(1+$G$36) -> 16716.732 | S19: =R19*(1+$G$36) -> 17218.234 | T19: =S19*(1+$G$36) -> 17734.781 | ... V19: =U19*(1+$G$36) -> 18814.829
J20: Administrative/G&A | L20: =G31 -> 10000 | M20: =L20*(1+$G$36) -> 10300 | N20: =M20*(1+$G$36) -> 10609 | O20: =N20*(1+$G$36) -> 10927.27 | P20: =O20*(1+$G$36) -> 11255.088 | Q20: =P20*(1+$G$36) -> 11592.741 | R20: =Q20*(1+$G$36) -> 11940.523 | S20: =R20*(1+$G$36) -> 12298.739 | T20: =S20*(1+$G$36) -> 12667.701 | ... V20: =U20*(1+$G$36) -> 13439.164
C21: Revenue Assumptions | J21: Insurance | L21: =G32 -> 20000 | M21: =L21*(1+$G$36) -> 20600 | N21: =M21*(1+$G$36) -> 21218 | O21: =N21*(1+$G$36) -> 21854.54 | P21: =O21*(1+$G$36) -> 22510.176 | Q21: =P21*(1+$G$36) -> 23185.481 | R21: =Q21*(1+$G$36) -> 23881.046 | S21: =R21*(1+$G$36) -> 24597.477 | T21: =S21*(1+$G$36) -> 25335.402 | ... V21: =U21*(1+$G$36) -> 26878.328
D22: Credit Loss | G22: 0.02 | J22: Management Fee (% of EGI) | L22: =L13*$G$33 -> 15032.251 | M22: =M13*$G$33 -> 15110.764 | N22: =N13*$G$33 -> 16980.097 | O22: =O13*$G$33 -> 18967.929 | P22: =P13*$G$33 -> 20052.419 | Q22: =Q13*$G$33 -> 21805.72 | R22: =R13*$G$33 -> 23010.402 | S22: =S13*$G$33 -> 23824.507 | ... V22: =V13*$G$33 -> 26448.543
D23: Year 1 Other Income (Per Unit Per Year) | G23: 2500 | J23: Real Estate Taxes | L23: =G34 -> 25000 | M23: =L23*(1+$G$37) -> 25937.5 | N23: =M23*(1+$G$37) -> 26910.156 | O23: =N23*(1+$G$37) -> 27919.287 | P23: =O23*(1+$G$37) -> 28966.26 | Q23: =P23*(1+$G$37) -> 30052.495 | R23: =Q23*(1+$G$37) -> 31179.464 | S23: =R23*(1+$G$37) -> 32348.694 | T23: =S23*(1+$G$37) -> 33561.77 | ... V23: =U23*(1+$G$37) -> 36126.099
D24: Other Income Growth | G24: 0.02 | J24: Reserves | L24: =G35 -> 250 | M24: =L24*(1+$G$36) -> 257.5 | N24: =M24*(1+$G$36) -> 265.225 | O24: =N24*(1+$G$36) -> 273.18175 | P24: =O24*(1+$G$36) -> 281.3772 | Q24: =P24*(1+$G$36) -> 289.81852 | R24: =Q24*(1+$G$36) -> 298.51307 | S24: =R24*(1+$G$36) -> 307.46847 | T24: =S24*(1+$G$36) -> 316.69252 | ... V24: =U24*(1+$G$36) -> 335.97909
J25: Total Operating Expenses | L25: =SUM(L16:L24) -> 188282.25 | M25: =SUM(M16:M24) -> 193745.76 | N25: =SUM(N16:N24) -> 201168.68 | O25: =SUM(O16:O24) -> 208883.99 | P25: =SUM(P16:P24) -> 215875.36 | Q25: =SUM(Q16:Q24) -> 223720.6 | R25: =SUM(R16:R24) -> 231208.12 | S25: =SUM(S16:S24) -> 238502 | ... V25: =SUM(V16:V24) -> 261810.24
C26: Expense Assumptions
D27: Payroll (Year 1) | G27: 55000 | J27: Net Operating Income | L27: =L13-L25 -> 312792.77 | M27: =M13-M25 -> 309946.36 | N27: =N13-N25 -> 364834.54 | O27: =O13-O25 -> 423380.29 | P27: =P13-P25 -> 452538.6 | Q27: =Q13-Q25 -> 503136.74 | R27: =R13-R25 -> 535805.29 | S27: =S13-S25 -> 555648.23 | ... V27: =V13-V25 -> 619807.84
D28: Utilities (Year 1) | G28: 34000
D29: Contracts (Year 1) | G29: 15000 | J29: Capital Expenses
D30: Repairs & Maintenance (per unit per year) | G30: 500 | J30: Renovation Schedule | L30: =IF(L6<=$G$40,$G$41/$G$40,0) -> 111250 | M30: =IF(M6<=$G$40,$G$41/$G$40,0) -> 111250 | N30: =IF(N6<=$G$40,$G$41/$G$40,0) -> 111250 | O30: =IF(O6<=$G$40,$G$41/$G$40,0) -> 111250 | P30: =IF(P6<=$G$40,$G$41/$G$40,0) -> 0 | Q30: =IF(Q6<=$G$40,$G$41/$G$40,0) -> 0 | R30: =IF(R6<=$G$40,$G$41/$G$40,0) -> 0 | S30: =IF(S6<=$G$40,$G$41/$G$40,0) -> 0 | ... V30: =IF(V6<=$G$40,$G$41/$G$40,0) -> 0
D31: Administrative/G&A (Year 1) | G31: 10000 | J31: Façade Project | L31: 0 | M31: 0 | N31: 0 | O31: 0 | P31: 0 | Q31: 0 | R31: 0 | S31: 0 | T31: 0 | U31: 0
D32: Insurance (Year 1) | G32: 20000 | J32: Roof Replacement | L32: 0 | M32: 0 | N32: 0 | O32: 0 | P32: 0 | Q32: 0 | R32: 0 | S32: 0 | T32: 0 | U32: 0
D33: Management Fee (% of EGI) | G33: 0.03 | J33: Total Capital Expenses | L33: =SUM(L30:L32) -> 111250 | M33: =SUM(M30:M32) -> 111250 | N33: =SUM(N30:N32) -> 111250 | O33: =SUM(O30:O32) -> 111250 | P33: =SUM(P30:P32) -> 0 | Q33: =SUM(Q30:Q32) -> 0 | R33: =SUM(R30:R32) -> 0 | S33: =SUM(S30:S32) -> 0 | ... U33: =SUM(U30:U32) -> 0
D34: Real Estate Taxes (Year 1) | G34: 25000
D35: Reserves (per unit per year) | G35: 250 | J35: Net Cash Flow Before Debt | L35: =L27-L33 -> 201542.77 | M35: =M27-M33 -> 198696.36 | N35: =N27-N33 -> 253584.54 | O35: =O27-O33 -> 312130.29 | P35: =P27-P33 -> 452538.6 | Q35: =Q27-Q33 -> 503136.74 | R35: =R27-R33 -> 535805.29 | S35: =S27-S33 -> 555648.23 | ... U35: =U27-U33 -> 597620.11
D36: Expense Growth | G36: 0.03
D37: Real Estate Tax Growth | G37: 0.0375 | J37: Debt Service | L37: ='Debt Amortization Schedule'!B8 -> 208900.77 | M37: =L37 -> 208900.77 | N37: =M37 -> 208900.77 | O37: =N37 -> 208900.77 | P37: =O37 -> 208900.77 | Q37: =P37 -> 208900.77 | R37: =Q37 -> 208900.77 | S37: =R37 -> 208900.77 | T37: =S37 -> 208900.77 | U37: =T37 -> 208900.77
J38: Total Debt Service | L38: =L37 -> 208900.77 | M38: =M37 -> 208900.77 | N38: =N37 -> 208900.77 | O38: =O37 -> 208900.77 | P38: =P37 -> 208900.77 | Q38: =Q37 -> 208900.77 | R38: =R37 -> 208900.77 | S38: =S37 -> 208900.77 | T38: =T37 -> 208900.77 | U38: =U37*10 -> 2089007.7
C39: Capital Expense Assumptions
D40: Renovation Schedule | G40: 4 | J40: Net Cash Flow After Debt | L40: =L35-L37 -> -7357.9946 | M40: =M35-M37 -> -10204.406 | N40: =N35-N37 -> 44683.772 | O40: =O35-O37 -> 103229.52 | P40: =P35-P37 -> 243637.83 | Q40: =Q35-Q37 -> 294235.97 | R40: =R35-R37 -> 326904.52 | S40: =S35-S37 -> 346747.47 | ... U40: =U35-U37 -> 388719.34
D41: Total Renovation Expense | G41: 445000
D42: Façade Project | J42: Unlevered Analysis
D43: Total Façade Expense | J43: Purchase Price | K43: =-SUM('Sources & Uses'!J15:J16) -> -6597500
D44: Roof Replacement Project | J44: Unlevered Cashflow | K44: 0 | L44: =L35 -> 201542.77 | M44: =M35 -> 198696.36 | N44: =N35 -> 253584.54 | O44: =O35 -> 312130.29 | P44: =P35 -> 452538.6 | Q44: =Q35 -> 503136.74 | R44: =R35 -> 535805.29 | S44: =S35 -> 555648.23 | ... U44: =U35 -> 597620.11
...

Sheet Rent Roll
B1: Property Rent Roll
B6: "T-12" Property Rent Roll | I6: Year | J6: 0 | K6: 1 | L6: =+K6+1 -> 2 | M6: =+L6+1 -> 3 | N6: =+M6+1 -> 4 | O6: =+N6+1 -> 5 | P6: =+O6+1 -> 6 | Q6: =+P6+1 -> 7 | R6: =+Q6+1 -> 8 | S6: =+R6+1 -> 9 | ... U6: =+T6+1 -> 11
B7: Unit | C7: # of Bedrooms | D7: Unit SF | E7: Monthly Rent | F7: $ PSF | G7: T-12 Annual Rent | I7: Date | J7: ='Assumptions & Cash Flow'!K7 -> 46022 | K7: ='Assumptions & Cash Flow'!L7 -> 46387 | L7: =EDATE(K7,12) -> 46752 | M7: =EDATE(L7,12) -> 47118 | N7: =EDATE(M7,12) -> 47483 | O7: =EDATE(N7,12) -> 47848 | P7: =EDATE(O7,12) -> 48213 | Q7: =EDATE(P7,12) -> 48579 | R7: =EDATE(Q7,12) -> 48944 | S7: =EDATE(R7,12) -> 49309 | ... U7: =EDATE(T7,12) -> 50040
B8: 1A | C8: 1 | D8: 650 | E8: 1100 | F8: =+E8/D8 -> 1.6923077 | G8: =E8*12 -> 13200
B9: 1B | C9: 1 | D9: 675 | E9: 1125 | F9: =+E9/D9 -> 1.6666667 | G9: =E9*12 -> 13500 | I9: 1 Bedroom Rent Growth Rate | K9: 0.06 | L9: 0.065 | M9: 0.07 | N9: 0.065 | O9: 0.06 | P9: 0.035 | Q9: 0.035 | R9: 0.035 | S9: 0.035 | T9: 0.035 | U9: 0.035
B10: 2A | C10: 1 | D10: 700 | E10: 1150 | F10: =+E10/D10 -> 1.6428571 | G10: =E10*12 -> 13800 | I10: 2 Bedroom Rent Growth Rate | K10: 0.065 | L10: 0.07 | M10: 0.075 | N10: 0.07 | O10: 0.065 | P10: 0.04 | Q10: 0.04 | R10: 0.04 | S10: 0.04 | T10: 0.04 | U10: 0.04
B11: 2B | C11: 1 | D11: 725 | E11: 1175 | F11: =+E11/D11 -> 1.6206897 | G11: =E11*12 -> 14100
B12: 3A | C12: 1 | D12: 725 | E12: 1200 | F12: =+E12/D12 -> 1.6551724 | G12: =E12*12 -> 14400
B13: 3B | C13: 1 | D13: 750 | E13: 1225 | F13: =+E13/D13 -> 1.6333333 | G13: =E13*12 -> 14700
B14: 4A | C14: 1 | D14: 750 | E14: 1250 | F14: =+E14/D14 -> 1.6666667 | G14: =E14*12 -> 15000 | I14: Annual 1 Bedroom Rent | J14: =SUM(G8:G25) -> 283500 | K14: =J14*(1+K9) -> 300510 | L14: =+K14*(1+L9) -> 320043.15 | M14: =+L14*(1+M9) -> 342446.17 | N14: =+M14*(1+N9) -> 364705.17 | O14: =+N14*(1+O9) -> 386587.48 | P14: =+O14*(1+P9) -> 400118.04 | Q14: =+P14*(1+Q9) -> 414122.18 | R14: =+Q14*(1+R9) -> 428616.45 | S14: =+R14*(1+S9) -> 443618.03 | ... U14: =+T14*(1+U9) -> 475214.72
B15: 4B | C15: 1 | D15: 750 | E15: 1275 | F15: =+E15/D15 -> 1.7 | G15: =E15*12 -> 15300 | I15: Annual 2 Bedroom Rent | J15: =SUM(G26:G35) -> 205500 | K15: =J15*(1+K10) -> 218857.5 | L15: =+K15*(1+L10) -> 234177.53 | M15: =+L15*(1+M10) -> 251740.84 | N15: =+M15*(1+N10) -> 269362.7 | O15: =+N15*(1+O10) -> 286871.27 | P15: =+O15*(1+P10) -> 298346.12 | Q15: =+P15*(1+Q10) -> 310279.97 | R15: =+Q15*(1+R10) -> 322691.17 | S15: =+R15*(1+S10) -> 335598.81 | ... U15: =+T15*(1+U10) -> 362983.68
B16: 5A | C16: 1 | D16: 775 | E16: 1300 | F16: =+E16/D16 -> 1.6774194 | G16: =E16*12 -> 15600
B17: 5B | C17: 1 | D17: 775 | E17: 1325 | F17: =+E17/D17 -> 1.7096774 | G17: =E17*12 -> 15900 | I17: Total Gross Potential Rent | J17: =SUM(J14:J15) -> 489000 | K17: =SUM(K14:K15) -> 519367.5 | L17: =SUM(L14:L15) -> 554220.68 | M17: =SUM(M14:M15) -> 594187.01 | N17: =SUM(N14:N15) -> 634067.87 | O17: =SUM(O14:O15) -> 673458.76 | P17: =SUM(P14:P15) -> 698464.17 | Q17: =SUM(Q14:Q15) -> 724402.14 | ... U17: =SUM(U14:U15) -> 838198.4
B18: 6A | C18: 1 | D18: 800 | E18: 1350 | F18: =+E18/D18 -> 1.6875 | G18: =E18*12 -> 16200
B19: 6B | C19: 1 | D19: 800 | E19: 1375 | F19: =+E19/D19 -> 1.71875 | G19: =E19*12 -> 16500 | I19: Vacancy Rate | K19: 0.15 | L19: 0.2 | M19: 0.15 | N19: 0.1 | O19: 0.1 | P19: 0.05 | Q19: 0.03 | R19: 0.03 | S19: 0.03 | T19: 0.03 | U19: 0.03
B20: 7A | C20: 1 | D20: 820 | E20: 1400 | F20: =+E20/D20 -> 1.7073171 | G20: =E20*12 -> 16800
B21: 7B | C21: 1 | D21: 820 | E21: 1425 | F21: =+E21/D21 -> 1.7378049 | G21: =E21*12 -> 17100 | I21: Vacancy Allowance | K21: =-K19*K17 -> -77905.125 | L21: =-L19*L17 -> -110844.14 | M21: =-M19*M17 -> -89128.051 | N21: =-N19*N17 -> -63406.787 | O21: =-O19*O17 -> -67345.876 | P21: =-P19*P17 -> -34923.208 | Q21: =-Q19*Q17 -> -21732.064 | R21: =-R19*R17 -> -22539.229 | ... U21: =-U19*U17 -> -25145.952
B22: 8A | C22: 1 | D22: 850 | E22: 1450 | F22: =+E22/D22 -> 1.7058824 | G22: =E22*12 -> 17400
B23: 8B | C23: 1 | D23: 850 | E23: 1475 | F23: =+E23/D23 -> 1.7352941 | G23: =E23*12 -> 17700 | I23: Total Rent Growth CAGR (5-Year ) | J23: =(O17/J17)^(1/5)-1 -> 0.066106101 | K23: Note: CAGR Formula is: =(Ending Balance/Starting Balance)^(1/Number of Years) – 1
B24: 9A | C24: 1 | D24: 875 | E24: 1500 | F24: =+E24/D24 -> 1.7142857 | G24: =E24*12 -> 18000 | I24: Total Rent Growth CAGR (10-Year ) | J24: =(U17/J17)^(1/10)-1 -> 0.055367696
B25: 9B | C25: 1 | D25: 875 | E25: 1525 | F25: =+E25/D25 -> 1.7428571 | G25: =E25*12 -> 18300
B26: 10A | C26: 2 | D26: 900 | E26: 1600 | F26: =+E26/D26 -> 1.7777778 | G26: =E26*12 -> 19200
B27: 10B | C27: 2 | D27: 900 | E27: 1625 | F27: =+E27/D27 -> 1.8055556 | G27: =E27*12 -> 19500
B28: 11A | C28: 2 | D28: 925 | E28: 1650 | F28: =+E28/D28 -> 1.7837838 | G28: =E28*12 -> 19800
B29: 11B | C29: 2 | D29: 950 | E29: 1675 | F29: =+E29/D29 -> 1.7631579 | G29: =E29*12 -> 20100
B30: 12A | C30: 2 | D30: 975 | E30: 1700 | F30: =+E30/D30 -> 1.7435897 | G30: =E30*12 -> 20400
B31: 12B | C31: 2 | D31: 1000 | E31: 1725 | F31: =+E31/D31 -> 1.725 | G31: =E31*12 -> 20700
B32: 13A | C32: 2 | D32: 1025 | E32: 1750 | F32: =+E32/D32 -> 1.7073171 | G32: =E32*12 -> 21000
B33: 13B | C33: 2 | D33: 1050 | E33: 1775 | F33: =+E33/D33 -> 1.6904762 | G33: =E33*12 -> 21300
B34: 14A | C34: 2 | D34: 1075 | E34: 1800 | F34: =+E34/D34 -> 1.6744186 | G34: =E34*12 -> 21600
B35: 14B | C35: 2 | D35: 1100 | E35: 1825 | F35: =+E35/D35 -> 1.6590909 | G35: =E35*12 -> 21900
B36: Total | C36: =COUNTA(C8:C35) -> 28 | D36: =SUM(D8:D35) -> 23865 | E36: =SUM(E8:E35) -> 40750 | F36: =+SUMPRODUCT(F8:F35,D8:D35)/D36 -> 1.7075215 | G36: =SUM(G8:G35) -> 489000

Sheet Sources & Uses
B1: Sources & Uses
B6: Property SF | C6: ='Assumptions & Cash Flow'!G10 -> 23865
B8: Sources & Uses
D9: Day 1 | G9: Future Funding | J9: Total Stack
B10: Sources | D10: Total | E10: PRSF | F10: % Total | G10: Total | H10: PRSF | I10: % Total | J10: Total | K10: PRSF | L10: % Total
B11: Debt | D11: ='Assumptions & Cash Flow'!G48 -> 3127927.7 | E11: =D11/$C$6 -> 131.06758 | F11: =D11/D$13 -> 0.47131486 | G11: 0 | H11: =G11/$C$6 -> 0 | I11: =G11/G$13 -> 0 | J11: =D11+G11 -> 3127927.7 | K11: =J11/$C$6 -> 131.06758 | L11: =J11/$J$13 -> 0.44169794
B12: Equity | D12: =D20-D11 -> 3508671.4 | E12: =D12/$C$6 -> 147.02164 | F12: =D12/D$13 -> 0.52868514 | G12: =G20-G11 -> 445000 | H12: =G12/$C$6 -> 18.646554 | I12: =G12/G$13 -> 1 | J12: =D12+G12 -> 3953671.4 | K12: =J12/$C$6 -> 165.66819 | L12: =J12/$J$13 -> 0.55830206
B13: Total Sources | D13: =SUM(D11:D12) -> 6636599.1 | E13: =SUM(E11:E12) -> 278.08921 | F13: =D13/D$13 -> 1 | G13: =SUM(G11:G12) -> 445000 | H13: =SUM(H11:H12) -> 18.646554 | I13: =G13/G$13 -> 1 | J13: =SUM(J11:J12) -> 7081599.1 | K13: =SUM(K11:K12) -> 296.73577 | L13: =SUM(L11:L12) -> 1
B14: Uses | D14: Total | E14: PRSF | F14: % Total | G14: Total | H14: PRSF | I14: % Total | J14: Total | K14: PRSF | L14: Total
B15: Property Purchase Price | D15: ='Assumptions & Cash Flow'!G14 -> 6500000 | E15: =D15/$C$6 -> 272.36539 | F15: =D15/D$20 -> 0.9794173 | G15: 0 | H15: =G15/$C$6 -> 0 | I15: =G15/G$20 -> 0 | J15: =D15+G15 -> 6500000 | K15: =J15/$C$6 -> 272.36539 | L15: =J15/$J$20 -> 0.91787178
B16: Closing Costs | D16: ='Assumptions & Cash Flow'!G16 -> 97500 | E16: =D16/$C$6 -> 4.0854808 | F16: =D16/D$20 -> 0.01469126 | G16: 0 | H16: =G16/$C$6 -> 0 | I16: =G16/G$20 -> 0 | J16: =D16+G16 -> 97500 | K16: =J16/$C$6 -> 4.0854808 | L16: =J16/$J$20 -> 0.013768077
B17: Debt Origination | D17: =+J11*'Assumptions & Cash Flow'!$G$17 -> 39099.097 | E17: =D17/$C$6 -> 1.6383447 | F17: =D17/D$20 -> 0.0058914357 | G17: 0 | H17: =G17/$C$6 -> 0 | I17: =G17/G$20 -> 0 | J17: =D17+G17 -> 39099.097 | K17: =J17/$C$6 -> 1.6383447 | L17: =J17/$J$20 -> 0.0055212243
B18: Renovation Hard Costs | D18: =E18*$C$6 -> 0 | E18: 0 | F18: =D18/D$20 -> 0 | G18: =H18*C6 -> 445000 | H18: ='Assumptions & Cash Flow'!G41/'Assumptions & Cash Flow'!G10 -> 18.646554 | I18: =G18/G$20 -> 1 | J18: =D18+G18 -> 445000 | K18: =J18/$C$6 -> 18.646554 | L18: =J18/$J$20 -> 0.062838914
B19: Renovation Soft Costs | D19: =E19*$C$6 -> 0 | E19: 0 | F19: =D19/D$20 -> 0 | G19: =H19*$C$6 -> 0 | H19: 0 | I19: =G19/G$20 -> 0 | J19: =D19+G19 -> 0 | K19: =J19/$C$6 -> 0 | L19: =J19/$J$20 -> 0
B20: Total Uses | D20: =SUM(D15:D19) -> 6636599.1 | E20: =SUM(E15:E19) -> 278.08921 | F20: =D20/D$20 -> 1 | G20: =SUM(G15:G19) -> 445000 | H20: =SUM(H15:H19) -> 18.646554 | I20: =G20/G$20 -> 1 | J20: =SUM(J15:J19) -> 7081599.1 | K20: =SUM(K15:K19) -> 296.73577 | L20: =SUM(L15:L19) -> 1

Sheet Debt Sizing
B1: Debt Sizing
C8: DSCR | F8: Debt Yield | I8: LTV
C9: Year 1 NOI | D9: ='Assumptions & Cash Flow'!L27 -> 312792.77 | F9: Year 1 NOI | G9: ='Assumptions & Cash Flow'!L27 -> 312792.77 | I9: Property Purchase Price | J9: ='Assumptions & Cash Flow'!G14 -> 6500000
C10: DSCR | D10: 1.25 | F10: Debt Yield | G10: 0.1 | I10: LTV | J10: 0.65
C11: Debt Service | D11: =D9/D10 -> 250234.22 | F11: Loan Amount | G11: =G9/G10 -> 3127927.7 | I11: Loan Amount | J11: =J9*J10 -> 4225000
C12: Interest Rate | D12: 0.0532
C13: # of years (Amortization Term) | D13: 30
C14: Loan Amount | D14: =PV(D12/12,D13*12,-D11/12) -> 3746824.7
C16: Loan Choice | D16: =G11 -> 3127927.7

Sheet Debt Amortization Schedule
A1: Loan Assumptions
A2: Loan Amount | B2: ='Debt Sizing'!D16 -> 3127927.7
A3: Interest Rate | B3: ='Assumptions & Cash Flow'!G51 -> 0.0532
A4: Loan Term yrs) | B4: ='Assumptions & Cash Flow'!G49 -> 10
A5: Amortization Term | B5: ='Assumptions & Cash Flow'!G50 -> 30
A6: Payments / Year | B6: ='Assumptions & Cash Flow'!G52 -> 12
A7: Monthly Payment (Debt Service) | B7: =E14 -> 17408.397
A8: Annual Payment (Debt Service) | B8: =B7*12 -> 208900.77
B11: Starting | E11: Total | F11: Ending
A12: Month | B12: Balance | C12: Interest Payment | D12: Principal Payment | E12: Payment | F12: Balance
A13: 0
A14: 1 | B14: =B2 -> 3127927.7 | C14: =B14*($B$3/12) -> 13867.146 | D14: =E14-C14 -> 3541.2511 | E14: =PMT($B$3/12,$B$5*12,-$B$2) -> 17408.397 | F14: =B14-D14 -> 3124386.5
A15: 2 | B15: =F14 -> 3124386.5 | C15: =B15*($B$3/12) -> 13851.447 | D15: =E15-C15 -> 3556.9506 | E15: =PMT($B$3/12,$B$5*12,-$B$2) -> 17408.397 | F15: =B15-D15 -> 3120829.5
A16: 3 | B16: =F15 -> 3120829.5 | C16: =B16*($B$3/12) -> 13835.678 | D16: =E16-C16 -> 3572.7198 | E16: =PMT($B$3/12,$B$5*12,-$B$2) -> 17408.397 | F16: =B16-D16 -> 3117256.8
A17: 4 | B17: =F16 -> 3117256.8 | C17: =B17*($B$3/12) -> 13819.839 | D17: =E17-C17 -> 3588.5588 | E17: =PMT($B$3/12,$B$5*12,-$B$2) -> 17408.397 | F17: =B17-D17 -> 3113668.3
A18: 5 | B18: =F17 -> 3113668.3 | C18: =B18*($B$3/12) -> 13803.929 | D18: =E18-C18 -> 3604.4681 | E18: =PMT($B$3/12,$B$5*12,-$B$2) -> 17408.397 | F18: =B18-D18 -> 3110063.8
A19: 6 | B19: =F18 -> 3110063.8 | C19: =B19*($B$3/12) -> 13787.949 | D19: =E19-C19 -> 3620.4479 | E19: =PMT($B$3/12,$B$5*12,-$B$2) -> 17408.397 | F19: =B19-D19 -> 3106443.3
A20: 7 | B20: =F19 -> 3106443.3 | C20: =B20*($B$3/12) -> 13771.899 | D20: =E20-C20 -> 3636.4986 | E20: =PMT($B$3/12,$B$5*12,-$B$2) -> 17408.397 | F20: =B20-D20 -> 3102806.8
A21: 8 | B21: =F20 -> 3102806.8 | C21: =B21*($B$3/12) -> 13755.777 | D21: =E21-C21 -> 3652.6204 | E21: =PMT($B$3/12,$B$5*12,-$B$2) -> 17408.397 | F21: =B21-D21 -> 3099154.2
A22: 9 | B22: =F21 -> 3099154.2 | C22: =B22*($B$3/12) -> 13739.584 | D22: =E22-C22 -> 3668.8137 | E22: =PMT($B$3/12,$B$5*12,-$B$2) -> 17408.397 | F22: =B22-D22 -> 3095485.4
A23: 10 | B23: =F22 -> 3095485.4 | C23: =B23*($B$3/12) -> 13723.319 | D23: =E23-C23 -> 3685.0787 | E23: =PMT($B$3/12,$B$5*12,-$B$2) -> 17408.397 | F23: =B23-D23 -> 3091800.3
A24: 11 | B24: =F23 -> 3091800.3 | C24: =B24*($B$3/12) -> 13706.981 | D24: =E24-C24 -> 3701.4159 | E24: =PMT($B$3/12,$B$5*12,-$B$2) -> 17408.397 | F24: =B24-D24 -> 3088098.9
A25: 12 | B25: =F24 -> 3088098.9 | C25: =B25*($B$3/12) -> 13690.572 | D25: =E25-C25 -> 3717.8255 | E25: =PMT($B$3/12,$B$5*12,-$B$2) -> 17408.397 | F25: =B25-D25 -> 3084381.1
A26: 13 | B26: =F25 -> 3084381.1 | C26: =B26*($B$3/12) -> 13674.09 | D26: =E26-C26 -> 3734.3079 | E26: =PMT($B$3/12,$B$5*12,-$B$2) -> 17408.397 | F26: =B26-D26 -> 3080646.8
... A313: 300 | B313: =F312 -> 928646.48 | C313: =B313*($B$3/12) -> 4116.9994 | D313: =E313-C313 -> 13291.398 | E313: =PMT($B$3/12,$B$5*12,-$B$2) -> 17408.397 | F313: =B313-D313 -> 915355.08
A314: =A313+1 -> 301 | B314: =F313 -> 915355.08 | C314: =B314*($B$3/12) -> 4058.0742 | D314: =E314-C314 -> 13350.323 | E314: =PMT($B$3/12,$B$5*12,-$B$2) -> 17408.397 | F314: =B314-D314 -> 902004.76
A315: =A314+1 -> 302 | B315: =F314 -> 902004.76 | C315: =B315*($B$3/12) -> 3998.8878 | D315: =E315-C315 -> 13409.51 | E315: =PMT($B$3/12,$B$5*12,-$B$2) -> 17408.397 | F315: =B315-D315 -> 888595.25
A316: =A315+1 -> 303 | B316: =F315 -> 888595.25 | C316: =B316*($B$3/12) -> 3939.4389 | D316: =E316-C316 -> 13468.958 | E316: =PMT($B$3/12,$B$5*12,-$B$2) -> 17408.397 | F316: =B316-D316 -> 875126.29
A317: =A316+1 -> 304 | B317: =F316 -> 875126.29 | C317: =B317*($B$3/12) -> 3879.7265 | D317: =E317-C317 -> 13528.671 | E317: =PMT($B$3/12,$B$5*12,-$B$2) -> 17408.397 | F317: =B317-D317 -> 861597.62
A318: =A317+1 -> 305 | B318: =F317 -> 861597.62 | C318: =B318*($B$3/12) -> 3819.7494 | D318: =E318-C318 -> 13588.648 | E318: =PMT($B$3/12,$B$5*12,-$B$2) -> 17408.397 | F318: =B318-D318 -> 848008.97
A319: =A318+1 -> 306 | B319: =F318 -> 848008.97 | C319: =B319*($B$3/12) -> 3759.5064 | D319: =E319-C319 -> 13648.891 | E319: =PMT($B$3/12,$B$5*12,-$B$2) -> 17408.397 | F319: =B319-D319 -> 834360.08
A320: =A319+1 -> 307 | B320: =F319 -> 834360.08 | C320: =B320*($B$3/12) -> 3698.9963 | D320: =E320-C320 -> 13709.401 | E320: =PMT($B$3/12,$B$5*12,-$B$2) -> 17408.397 | F320: =B320-D320 -> 820650.68
A321: =A320+1 -> 308 | B321: =F320 -> 820650.68 | C321: =B321*($B$3/12) -> 3638.218 | D321: =E321-C321 -> 13770.179 | E321: =PMT($B$3/12,$B$5*12,-$B$2) -> 17408.397 | F321: =B321-D321 -> 806880.5
A322: =A321+1 -> 309 | B322: =F321 -> 806880.5 | C322: =B322*($B$3/12) -> 3577.1702 | D322: =E322-C322 -> 13831.227 | E322: =PMT($B$3/12,$B$5*12,-$B$2) -> 17408.397 | F322: =B322-D322 -> 793049.27
A323: =A322+1 -> 310 | B323: =F322 -> 793049.27 | C323: =B323*($B$3/12) -> 3515.8518 | D323: =E323-C323 -> 13892.546 | E323: =PMT($B$3/12,$B$5*12,-$B$2) -> 17408.397 | F323: =B323-D323 -> 779156.73
A324: =A323+1 -> 311 | B324: =F323 -> 779156.73 | C324: =B324*($B$3/12) -> 3454.2615 | D324: =E324-C324 -> 13954.136 | E324: =PMT($B$3/12,$B$5*12,-$B$2) -> 17408.397 | F324: =B324-D324 -> 765202.59
A325: =A324+1 -> 312 | B325: =F324 -> 765202.59 | C325: =B325*($B$3/12) -> 3392.3981 | D325: =E325-C325 -> 14015.999 | E325: =PMT($B$3/12,$B$5*12,-$B$2) -> 17408.397 | F325: =B325-D325 -> 751186.59
... A373: =A372+1 -> 360 | B373: =F372 -> 17331.561 | C373: =B373*($B$3/12) -> 76.836586 | D373: =E373-C373 -> 17331.561 | E373: =PMT($B$3/12,$B$5*12,-$B$2) -> 17408.397 | F373: =B373-D373 -> -2.4701876e-09
